<?xml version="1.0"?>
<robot xmlns:xacro="http://ros.org/wiki/xacro">
  <xacro:include filename="$(find abb_resources)/urdf/common_materials.xacro"/>
  
  <xacro:macro name="abb_irb6640_185_280" params="prefix">
    <!-- link list -->
    
    <link name="${prefix}base_link">
     <inertial>
        <mass value="6.215"/>
        <origin xyz="-0.04204 8.01E-05 0.07964" rpy="0 0 0"/>
        <inertia ixx="0.0247272" ixy="-8.0784E-05" ixz="0.00130902" iyy="0.0491285" iyz="-8.0419E-06" izz="0.0472376"/>
      </inertial>
      <collision name="collision">
      <origin xyz="0 0 0" rpy="0 0 0"/>
        <geometry>
          <mesh filename="package://abb_irb6640_description/meshes/irb6640_185_280/collision/base_link.stl"/>
        </geometry>
        <xacro:material_abb_yellow />
      </collision>
      <visual name="visual">
        <geometry>
          <mesh filename="package://abb_irb6640_description/meshes/irb6640_185_280/visual/base_link.dae"/>
        </geometry>
        <xacro:material_abb_orange />
      </visual>
    </link>
    
    <link name="${prefix}link_1">
      <inertial>
        <mass value="3.067" />
        <origin xyz="9.77E-05 -0.00012 0.23841" rpy="0 0 0"/>
        <inertia ixx="0.0142175" ixy="-1.28579E-05" ixz="-2.31364E-05" iyy="0.0144041" iyz="1.93404E-05" izz="0.0104533"/>
      </inertial>
      <collision name="collision">
        <geometry>
          <mesh filename="package://abb_irb6640_description/meshes/irb6640_185_280/collision/link_1.stl"/>
        </geometry>
        <xacro:material_abb_yellow />
      </collision>
      <visual name="visual">
        <origin xyz="0 0 0" rpy="0 0 0"/>
        <geometry>
          <mesh filename="package://abb_irb6640_description/meshes/irb6640_185_280/visual/link_1.dae"/>
        </geometry>
        <xacro:material_abb_orange />
      </visual>
    </link>
    
    
    <link name="${prefix}link_2">
      <inertial>
        <mass value="3.909"/>
        <origin xyz="0.00078 -0.00212 0.10124" rpy="0 0 0"/>
        <inertia ixx="0.0603111" ixy="9.83431E-06" ixz="5.72407E-05" iyy="0.041569" iyz="-0.00050497" izz="0.0259548"/>
      </inertial>
      <collision name="collision">
        <origin xyz="0 0 0" rpy="0 0 0"/>
        <geometry>
          <mesh filename="package://abb_irb6640_description/meshes/irb6640_185_280/collision/link_2.stl"/>
        </geometry>
        <xacro:material_abb_yellow />
      </collision>
      <visual name="visual">
        <origin xyz="0 0 0" rpy="0 0 0"/>
        <geometry>
          <mesh filename="package://abb_irb6640_description/meshes/irb6640_185_280/visual/link_2.dae"/>
        </geometry>
        <xacro:material_abb_orange />
      </visual>
    </link>
    
    
    
    <link name="${prefix}link_3">
      <inertial>
        <mass value="2.944"/>
        <origin xyz="0.02281 0.00106 0.05791" rpy="0 0 0"/>
        <inertia ixx="0.00835606" ixy="-8.01545E-05" ixz="0.00142884" iyy="0.016713" iyz="-0.000182227" izz="0.0126984"/>
      </inertial>
      <collision name="collision">
        <origin xyz="0 0 0" rpy="0 0 0"/>
        <geometry>          
          <mesh filename="package://abb_irb6640_description/meshes/irb6640_185_280/collision/link_3.stl"/>
        </geometry>
        <xacro:material_abb_yellow />
      </collision>
      <visual name="visual">
        <origin xyz="0 0 0" rpy="0 0 0"/>
        <geometry>
          <mesh filename="package://abb_irb6640_description/meshes/irb6640_185_280/visual/link_3.dae"/>
        </geometry>
        <xacro:material_abb_orange />
      </visual>
    </link>
    
    
    
    <link name="${prefix}link_4">
      <inertial>
        <mass value="1.328"/>
        <origin xyz="0.2247 0.00015 0.00041" rpy="0 0 0"/>
        <inertia ixx="0.00284661" ixy="-2.12765E-05" ixz="-1.6435E-05" iyy="0.00401346" iyz="1.31336E-05" izz="0.0052535"/>
      </inertial>
      <collision name="collision">
        <origin xyz="0 0 0" rpy="0 0 0"/>
        <geometry>
          <mesh filename="package://abb_irb6640_description/meshes/irb6640_185_280/collision/link_4.stl"/>
        </geometry>
        <xacro:material_abb_yellow />
      </collision>
      <visual name="visual">
        <origin xyz="0 0 0" rpy="0 0 0"/>
        <geometry>
          <mesh filename="package://abb_irb6640_description/meshes/irb6640_185_280/visual/link_4.dae"/>
        </geometry>
        <xacro:material_abb_orange />
      </visual>
    </link>
    <link name="${prefix}link_5">
      <inertial>
        <mass value="0.546"/>
        <origin xyz="-0.00109 3.68E-05 6.22E-05" rpy="0 0 0"/>
        <inertia ixx="0.000404891" ixy="1.61943E-06" ixz="8.46805E-07" iyy="0.000892825" iyz="-1.51792E-08" izz="0.000815468"/>
      </inertial>
      <collision name="collision">
        <origin xyz="0 0 0" rpy="0 0 0"/>
        <geometry>
          <mesh filename="package://abb_irb6640_description/meshes/irb6640_185_280/collision/link_5.stl"/>
        </geometry>
        <xacro:material_abb_yellow />
      </collision>
      <visual name="visual">
        <origin xyz="0 0 0" rpy="0 0 0"/>
        <geometry>
          <mesh filename="package://abb_irb6640_description/meshes/irb6640_185_280/visual/link_5.dae"/>
        </geometry>
        <xacro:material_abb_orange />
        <material name="yellow"/>
      </visual>
    </link>
    
    
    
    <link name="${prefix}link_6">
      <inertial>
        <mass value="0.137"/>
        <origin xyz="-0.00706 -0.00017 -1.32E-06" rpy="0 0 0"/>
        <inertia ixx="0.001" ixy="0" ixz="0" iyy="0.001" iyz="0" izz="0.001"/>
      </inertial>
      <collision name="collision">
        <origin xyz="0 0 0" rpy="0 0 0"/>
        <geometry>
          <mesh filename="package://abb_irb6640_description/meshes/irb6640_185_280/collision/link_6.stl"/>
        </geometry>
        <xacro:material_abb_yellow />
      </collision>
      <visual name="visual">
        <origin xyz="0 0 0" rpy="0 0 0"/>
        <geometry>
          <mesh filename="package://abb_irb6640_description/meshes/irb6640_185_280/visual/link_6.dae"/>
        </geometry>
        <xacro:material_abb_black />
        <material name="yellow"/>
      </visual>
    </link>
    <link name="${prefix}tool0"/>

    <!--Cylinder and piston -->
    <link name="${prefix}link_cylinder">
      <collision name="collision">
        <geometry>
          <mesh filename="package://abb_irb6640_description/meshes/irb6640_185_280/collision/cylinder_link.stl"/>
        </geometry>
      </collision>
      <visual name="visual">
        <geometry>
          <mesh filename="package://abb_irb6640_description/meshes/irb6640_185_280/visual/cylinder_link.dae"/>
        </geometry>
        <material name="yellow"/>
      </visual>
    </link>
    <link name="${prefix}link_piston">
      <collision name="collision">
        <geometry>
          <mesh filename="package://abb_irb6640_description/meshes/irb6640_185_280/collision/piston_link.stl"/>
        </geometry>
      </collision>
      <visual name="visual">
        <geometry>
          <mesh filename="package://abb_irb6640_description/meshes/irb6640_185_280/visual/piston_link.dae"/>
        </geometry>
        <material name="yellow"/>
      </visual>
    </link>
    <!-- end of link list -->

    <!-- joint list -->
    <joint type="revolute" name="${prefix}joint_1">
      <origin xyz="0 0 0.780" rpy="0 0 0"/>
      <axis xyz="0 0 1"/>
      <parent link="${prefix}base_link"/>
      <child link="${prefix}link_1"/>
      <limit effort="0" lower="-2.967" upper="2.967" velocity="1.7453"/>
    </joint>
    <joint type="revolute" name="${prefix}joint_2">
      <origin xyz="0.320 0 0" rpy="0 0 0"/>
      <axis xyz="0 1 0"/>
      <parent link="${prefix}link_1"/>
      <child link="${prefix}link_2"/>
      <limit effort="0" lower="-1.134" upper="1.4855" velocity="1.5707"/>
    </joint>
    <joint type="revolute" name="${prefix}joint_3">
      <origin xyz="0 0 1.075" rpy="0 0 0"/>
      <axis xyz="0 1 0"/>
      <parent link="${prefix}link_2"/>
      <child link="${prefix}link_3"/>
      <limit effort="0" lower="-3.142" upper="1.222" velocity="1.5707"/>
    </joint>
    <joint type="revolute" name="${prefix}joint_4">
      <origin xyz="0 0 0.2" rpy="0 0 0"/>
      <axis xyz="1 0 0"/>
      <parent link="${prefix}link_3"/>
      <child link="${prefix}link_4"/>
      <limit effort="0" lower="-5.236" upper="5.236" velocity="2.9671"/>
    </joint>
    <joint type="revolute" name="${prefix}joint_5">
      <origin xyz="1.392 0 0 " rpy="0 0 0"/>
      <axis xyz="0 1 0"/>
      <parent link="${prefix}link_4"/>
      <child link="${prefix}link_5"/>
      <limit effort="0" lower="-2.094" upper="2.094" velocity="2.4435"/>
    </joint>
    <joint type="revolute" name="${prefix}joint_6">
      <origin xyz="0.2 0 0 " rpy="0 0 0"/>
      <axis xyz="1 0 0"/>
      <parent link="${prefix}link_5"/>
      <child link="${prefix}link_6"/>
      <limit effort="0" lower="-6.283" upper="6.283" velocity="3.3161"/>
    </joint>
    <joint type="fixed" name="${prefix}joint_6-tool0">
      <parent link="${prefix}link_6"/>
      <child link="${prefix}tool0"/>
      <origin xyz="0 0 0" rpy="0 1.57079632679 0"/>
    </joint>
    <joint type="continuous" name="${prefix}joint_cylinder">
      <origin xyz="-0.3647 0 -0.1455" rpy="0 0 0"/>
      <axis xyz="0 1 0"/>
      <parent link="${prefix}link_1"/>
      <child link="${prefix}link_cylinder"/>
      <mimic joint="${prefix}joint_2" multiplier="-0.25"/>
    </joint>
    <joint type="continuous" name="${prefix}joint_piston">
      <origin xyz="-0.22 0 -0.0672" rpy="0 0 0"/>
      <axis xyz="0 1 0"/>
      <parent link="${prefix}link_2"/>
      <child link="${prefix}link_piston"/>
      <mimic joint="${prefix}joint_2" multiplier="-1.25"/>
    </joint>
    <!-- end of joint list -->

    <!-- ROS base_link to ABB World Coordinates transform -->
    <link name="${prefix}base" />
    <joint name="${prefix}base_link-base" type="fixed">
      <origin xyz="0 0 0" rpy="0 0 0"/>
      <parent link="${prefix}base_link"/>
      <child link="${prefix}base"/>
    </joint>
  </xacro:macro>
</robot>
